(async ()=>{
    // Assume:

    function load(val, cb){
        setTimeout(()=>{
            // Randomly throw an error
            if(Math.random() >= 0.5) {
                return cb(new Error(`${val} is wrong..`));
            }

            return cb(undefined, `${val} is sababa..`);
        }, 1000);
    }

    // Old way..
    load(5, (err, data) => {
        if(err) return cosnole.log(err);
        console.log(data);
    });

    // Modern way..
    try{
        const data = await loadP(5);
        console.log(data);
    }catch(e){
        console.log(e);
    }

    /**
     * The task: implement `loadP` that promisified `load`
     */
})();

(async ()=>{

    const fakeAjax = (path) => {
        return new Promise((resolve, reject) => {
            setTimeout(() => {

                // Randomly throw an error
                if(Math.random() >= 0.5) {
                    return reject(new Error(`${path} went wrong..`));
                }

                return resolve(`${path} went sababa..`);
            });
        });
    }

    /**
     * The task:
     * 1. Call `fakeAjax` N times in parallel
     * 2. Call `fakeAjax` N times in sequence
     * 3. Catch errors but only for failed executions
     */
})();

(async() => {

    const EventEmitter = require('events');

    class A extends EventEmitter{
        foo(){}
        boo(){}
        moo(){}
        async run(){
            setImmediate(() => {
                this.emit('something');
            });
        }
    }

    /**
     * The task:
     * 1. What's the problem?
     * 2. How to fix that?
     */

    try {

        const a = new A();

        a.on('something', () => {
            throw new Error('something went wrong..');
        });

        a.foo();
        a.boo();
        a.moo();
        await a.run();

    } catch (e) {
        console.error(e);
    }

})();

